<?xml version="1.0"?>
<robot xmlns:xacro="http://www.ros.org/wiki/xacro"  >

    <xacro:include filename="inertial_macros.xacro"/>

    <material name="white">
        <color rgba="1 1 1 1" />
    </material>

    <material name="orange">
        <color rgba="1 0.3 0.1 1" />
    </material>

    <material name="blue">
        <color rgba="0.2 0.2 1 1" />
    </material>

    <material name="black">
        <color rgba="0 0 0 1" />
    </material>
<!-- BASE LINK -->

    <link name="base_link">

    </link>

    <!-- FOOT LINK -->

    <joint name="foot_joint" type="fixed">
        <parent link="base_link"/>
        <child link="foot"/>
        <origin xyz="-0.05 0 0"/>
    </joint>

    <link name="foot">
        <visual>
            <origin xyz="0.05 0 0.01"/>
            <geometry>
                <box size="0.1 0.05 0.02"/>
            </geometry>
            <material name="white"/>
        </visual>
        <collision>
            <origin xyz="0.05 0 0.01"/>
            <geometry>
                <box size="0.1 0.05 0.02"/>
            </geometry>
            <material name="white"/>
        </collision>
        <xacro:inertial_box mass="1" x="0.1" y="0.05" z="0.02">
            <origin xyz="0.05 0 0.01" rpy="0 0 0"/>
        </xacro:inertial_box>
    </link>
    <gazebo reference="foot">
        <material>Gazebo/White</material>
    </gazebo>
    <!-- ANKLE_ROLL LINK -->

    <joint name="ankle_roll_joint" type="continuous">
        <parent link="foot"/>
        <child link="ankle_roll"/>
        <origin xyz="-0.01 0 0.01" rpy="0 ${pi/2} 0"/>
        <axis xyz="0 0 1"/>
    </joint>

    <link name="ankle_roll">
        <visual>
            <geometry>
                <cylinder radius="0.01" length="0.01"/>
            </geometry>
            <material name="blue"/>
        </visual>
        <collision>
            <geometry>
                <cylinder radius="0.01" length="0.01"/>
            </geometry>
            <material name="blue"/>
        </collision>
        <xacro:inertial_cylinder mass="0.1" radius="0.01" length="0.01">
            <origin xyz="0 0 0" rpy="0 0 0"/>
        </xacro:inertial_cylinder>
    </link>

    <!-- ANKLE_PITCH LINK -->

    <joint name="ankle_pitch_joint" type="continuous">
        <parent link="ankle_roll"/>
        <child link="ankle_pitch"/>
        <origin xyz="0 0 0" rpy="${pi/2} -${pi/2} 0"/>
        <axis xyz="0 0 1"/>
    </joint>

    <link name="ankle_pitch">
        <visual>
            <geometry>
                <cylinder radius="0.01" length="0.01"/>
            </geometry>
            <material name="black"/>
        </visual>
        <collision>
            <geometry>
                <cylinder radius="0.01" length="0.01"/>
            </geometry>
            <material name="black"/>
        </collision>
        <xacro:inertial_cylinder mass="0.1" radius="0.01" length="0.01">
            <origin xyz="0 0 0" rpy="0 0 0"/>
        </xacro:inertial_cylinder>
    </link>

    <!-- CALF LINK -->

    <joint name="calf_joint" type="fixed">
        <parent link="ankle_pitch"/>
        <child link="calf"/>
        <origin xyz="0 0 0" rpy="-${pi/2} 0 0"/>
        <axis xyz="0 0 1"/>
    </joint>

    <link name="calf">
        <visual>
            <origin xyz="0 0 0.2" rpy="0 0 0"/>
            <geometry>
                <cylinder radius="0.025" length="0.4"/>
            </geometry>
            <material name="white"/>
        </visual>
        <collision>
            <origin xyz="0 0 0.2" rpy="0 0 0"/>
            <geometry>
                <cylinder radius="0.025" length="0.4"/>
            </geometry>
            <material name="white"/>
        </collision>
        <xacro:inertial_cylinder mass="5" radius="0.025" length="0.4">
            <origin xyz="0 0 0.2" rpy="0 0 0"/>
        </xacro:inertial_cylinder>
    </link>

    <!-- KNEE LINK -->

    <joint name="knee_joint" type="continuous">
        <parent link="calf"/>
        <child link="knee"/>
        <origin xyz="0 0 0.4" rpy="${pi/2} 0 0"/>
        <axis xyz="0 0 1"/>
    </joint>

    <link name="knee">
        <visual>
            <geometry>
                <cylinder radius="0.01" length="0.01"/>
            </geometry>
            <material name="blue"/>
        </visual>
        <collision>
            <geometry>
                <cylinder radius="0.01" length="0.01"/>
            </geometry>
            <material name="blue"/>
        </collision>
        <xacro:inertial_cylinder mass="0.1" radius="0.01" length="0.01">
            <origin xyz="0 0 0" rpy="0 0 0"/>
        </xacro:inertial_cylinder>
    </link>

    <!-- THIGH LINK -->

    <joint name="thigh_joint" type="fixed">
        <parent link="knee"/>
        <child link="tight"/>
        <origin xyz="0 0 0" rpy="-${pi/2} 0 0"/>
        <axis xyz="0 0 1"/>
    </joint>

    <link name="tight">
        <visual>
            <origin xyz="0 0 0.2" rpy="0 0 0"/>
            <geometry>
                <cylinder radius="0.025" length="0.4"/>
            </geometry>
            <material name="white"/>
        </visual>
        <collision>
            <origin xyz="0 0 0.2" rpy="0 0 0"/>
            <geometry>
                <cylinder radius="0.025" length="0.4"/>
            </geometry>
            <material name="white"/>
        </collision>
        <xacro:inertial_cylinder mass="5" radius="0.025" length="0.4">
            <origin xyz="0 0 0.2" rpy="0 0 0"/>
        </xacro:inertial_cylinder>
    </link>

    <!-- HIP_YAW LINK -->

    <joint name="hip_yaw_joint" type="continuous">
        <parent link="tight"/>
        <child link="hip_yaw"/>
        <origin xyz="0 0 0.4" rpy="0 0 0"/>
        <axis xyz="0 0 1"/>
    </joint>

    <link name="hip_yaw">
        <visual>
            <geometry>
                <cylinder radius="0.01" length="0.01"/>
            </geometry>
            <material name="blue"/>
        </visual>
        <collision>
            <geometry>
                <cylinder radius="0.01" length="0.01"/>
            </geometry>
            <material name="blue"/>
        </collision>
        <xacro:inertial_cylinder mass="0.1" radius="0.01" length="0.01">
            <origin xyz="0 0 0" rpy="0 0 0"/>
        </xacro:inertial_cylinder>
    </link>

    <!-- HIP_PITCH LINK -->

    <joint name="hip_pitch_joint" type="continuous">
        <parent link="hip_yaw"/>
        <child link="hip_pitch"/>
        <origin xyz="0 0 0" rpy="${pi/2} 0 0"/>
        <axis xyz="0 0 1"/>
    </joint>

    <link name="hip_pitch">
        <visual>
            <geometry>
                <cylinder radius="0.01" length="0.01"/>
            </geometry>
            <material name="blue"/>
        </visual>
        <collision>
            <geometry>
                <cylinder radius="0.01" length="0.01"/>
            </geometry>
            <material name="blue"/>
        </collision>
        <xacro:inertial_cylinder mass="0.1" radius="0.01" length="0.01">
            <origin xyz="0 0 0" rpy="0 0 0"/>
        </xacro:inertial_cylinder>
    </link>

    <!-- HIP_ROLL LINK -->

    <joint name="hip_roll_joint" type="continuous">
        <parent link="hip_pitch"/>
        <child link="hip_roll"/>
        <origin xyz="0 0 0" rpy="-${pi/2} 0 0"/>
        <axis xyz="1 0 0"/>
    </joint>

    <link name="hip_roll">
        <visual>
            <geometry>
                <cylinder radius="0.01" length="0.01"/>
            </geometry>
            <material name="blue"/>
        </visual>
        <collision>
            <geometry>
                <cylinder radius="0.01" length="0.01"/>
            </geometry>
            <material name="blue"/>
        </collision>
        <xacro:inertial_cylinder mass="0.1" radius="0.01" length="0.01">
            <origin xyz="0 0 0" rpy="0 0 0"/>
        </xacro:inertial_cylinder>
    </link>

    <!-- WAIST LINK -->

    <joint name="waist_joint" type="fixed">
        <parent link="hip_roll"/>
        <child link="waist"/>
        <origin xyz="0 0 0" rpy="0 0 0"/>
        <axis xyz="0 0 1"/>
    </joint>

    <link name="waist">
        <visual>
            <origin xyz="0 0 0.157"/>
            <geometry>
                <box size="0.1 0.1 0.314"/>
            </geometry>
            <material name="white"/>
        </visual>
        <collision>
            <origin xyz="0 0 0.157"/>
            <geometry>
                <box size="0.1 0.1 0.314"/>
            </geometry>
            <material name="white"/>
        </collision>
        <xacro:inertial_box mass="20" x="0.1" y="0.1" z="0.314">
            <origin xyz="0 0 0.157" rpy="0 0 0"/>
        </xacro:inertial_box>
    </link>

    <!-- WAIST_FIX LINK -->

    <joint name="waist_fix_joint" type="fixed">
        <parent link="waist"/>
        <child link="waist_fix"/>
        <origin xyz="0 0 0" rpy="0 0 0"/>
    </joint>

    <link name="waist_fix">
        <visual>
            <origin xyz="0 0 -0.4" rpy="0 0 0"/>
            <geometry>
                <cylinder radius="0.01" length="2"/>
            </geometry>
            <material name="white"/>
        </visual>
        <!-- <collision>
            <origin xyz="0 0 -0.4" rpy="0 0 0"/>
            <geometry>
                <cylinder radius="0.01" length="2"/>
            </geometry>
            <material name="white"/>
        </collision> -->
        <xacro:inertial_cylinder mass="10000" radius="0.01" length="2">
            <origin xyz="0 0 -0.4" rpy="0 0 0"/>
        </xacro:inertial_cylinder>
    </link>

    <!-- WAIST_FIX LINK -->

    <!-- <joint name="waist_fix2_joint" type="fixed">
        <parent link="waist"/>
        <child link="waist_fix2"/>
        <origin xyz="0 0 0" rpy="0 0 0"/>
    </joint>

    <link name="waist_fix2">
        <visual>
            <origin xyz="0 0 -0.4" rpy="0 0 0"/>
            <geometry>
                <cylinder radius="0.01" length="0.6"/>
            </geometry>
            <material name="white"/>
        </visual>
        <collision>
            <origin xyz="0 0 -0.4" rpy="0 0 0"/>
            <geometry>
                <cylinder radius="0.01" length="0.6"/>
            </geometry>
            <material name="white"/>
        </collision>
        <xacro:inertial_cylinder mass="10000" radius="0.01" length="0.6">
            <origin xyz="0 0 -0.4" rpy="0 0 0"/>
        </xacro:inertial_cylinder>
    </link> -->

</robot> 